<robot name = "robot">
    <link name="Torso">
        <inertial>
            <origin xyz="0 0 1" rpy="0 0 0"/>
            <mass value="1" />
            <inertia ixx="100" ixy="0" ixz="0" iyy="100" iyz="0" izz="100" />
        </inertial>
        <visual>
            <origin xyz="0 0 1" rpy="0 0 0"/>
            <geometry>
                <sphere radius="0.5" />
            </geometry>
            <material name="Cyan">
                <color rgba="0 1.0 1.0 1.0"/>
            </material>
        </visual>
        <collision>
            <origin xyz="0 0 1" rpy="0 0 0"/>
            <geometry>
                <sphere radius="0.5" />
            </geometry>
        </collision>
    </link>
    <link name="UppperLeg0">
        <inertial>
            <origin xyz="0.5 0.0 0" rpy="0 0 0.0"/>
            <mass value="1" />
            <inertia ixx="100" ixy="0" ixz="0" iyy="100" iyz="0" izz="100" />
        </inertial>
        <visual>
            <origin xyz="0.5 0.0 0" rpy="0 0 0.0"/>
            <geometry>
                <box size="1 0.2 0.2" />
            </geometry>
            <material name="Cyan">
                <color rgba="0 1.0 1.0 1.0"/>
            </material>
        </visual>
        <collision>
            <origin xyz="0.5 0.0 0" rpy="0 0 0.0"/>
            <geometry>
                <box size="1 0.2 0.2" />
            </geometry>
        </collision>
    </link>
    <link name="LowerLeg0">
        <inertial>
            <origin xyz="0 0 -0.5" rpy="0 0 0.0"/>
            <mass value="1" />
            <inertia ixx="100" ixy="0" ixz="0" iyy="100" iyz="0" izz="100" />
        </inertial>
        <visual>
            <origin xyz="0 0 -0.5" rpy="0 0 0.0"/>
            <geometry>
                <box size="0.2 0.2 1" />
            </geometry>
            <material name="Cyan">
                <color rgba="0 1.0 1.0 1.0"/>
            </material>
        </visual>
        <collision>
            <origin xyz="0 0 -0.5" rpy="0 0 0.0"/>
            <geometry>
                <box size="0.2 0.2 1" />
            </geometry>
        </collision>
    </link>
    <joint name="Torso_UppperLeg0" type="revolute">
       <parent link="Torso"/>
       <child  link="UppperLeg0"/>
       <origin rpy="0 0 0" xyz="0.5 0.0 1"/>
     <axis xyz="0.0 1.0 0"/>
       <limit effort="0.0" lower="-3.14159" upper="3.14159" velocity="0.0"/>
    </joint>
    <joint name="UppperLeg0_LowerLeg0" type="revolute">
       <parent link="UppperLeg0"/>
       <child  link="LowerLeg0"/>
       <origin rpy="0 0 0" xyz="1.0 0.0 0"/>
     <axis xyz="0.0 1.0 0"/>
       <limit effort="0.0" lower="-3.14159" upper="3.14159" velocity="0.0"/>
    </joint>
    <link name="UppperLeg1">
        <inertial>
            <origin xyz="0.25000000000000006 0.4330127018922193 0" rpy="0 0 1.0471975511965976"/>
            <mass value="1" />
            <inertia ixx="100" ixy="0" ixz="0" iyy="100" iyz="0" izz="100" />
        </inertial>
        <visual>
            <origin xyz="0.25000000000000006 0.4330127018922193 0" rpy="0 0 1.0471975511965976"/>
            <geometry>
                <box size="1 0.2 0.2" />
            </geometry>
            <material name="Cyan">
                <color rgba="0 1.0 1.0 1.0"/>
            </material>
        </visual>
        <collision>
            <origin xyz="0.25000000000000006 0.4330127018922193 0" rpy="0 0 1.0471975511965976"/>
            <geometry>
                <box size="1 0.2 0.2" />
            </geometry>
        </collision>
    </link>
    <link name="LowerLeg1">
        <inertial>
            <origin xyz="0 0 -0.5" rpy="0 0 1.0471975511965976"/>
            <mass value="1" />
            <inertia ixx="100" ixy="0" ixz="0" iyy="100" iyz="0" izz="100" />
        </inertial>
        <visual>
            <origin xyz="0 0 -0.5" rpy="0 0 1.0471975511965976"/>
            <geometry>
                <box size="0.2 0.2 1" />
            </geometry>
            <material name="Cyan">
                <color rgba="0 1.0 1.0 1.0"/>
            </material>
        </visual>
        <collision>
            <origin xyz="0 0 -0.5" rpy="0 0 1.0471975511965976"/>
            <geometry>
                <box size="0.2 0.2 1" />
            </geometry>
        </collision>
    </link>
    <joint name="Torso_UppperLeg1" type="revolute">
       <parent link="Torso"/>
       <child  link="UppperLeg1"/>
       <origin rpy="0 0 0" xyz="0.25000000000000006 0.4330127018922193 1"/>
     <axis xyz="0.8660254037844386 0.5000000000000001 0"/>
       <limit effort="0.0" lower="-3.14159" upper="3.14159" velocity="0.0"/>
    </joint>
    <joint name="UppperLeg1_LowerLeg1" type="revolute">
       <parent link="UppperLeg1"/>
       <child  link="LowerLeg1"/>
       <origin rpy="0 0 0" xyz="0.5000000000000001 0.8660254037844386 0"/>
     <axis xyz="0.8660254037844386 0.5000000000000001 0"/>
       <limit effort="0.0" lower="-3.14159" upper="3.14159" velocity="0.0"/>
    </joint>
    <link name="UppperLeg2">
        <inertial>
            <origin xyz="-0.2499999999999999 0.43301270189221935 0" rpy="0 0 2.0943951023931953"/>
            <mass value="1" />
            <inertia ixx="100" ixy="0" ixz="0" iyy="100" iyz="0" izz="100" />
        </inertial>
        <visual>
            <origin xyz="-0.2499999999999999 0.43301270189221935 0" rpy="0 0 2.0943951023931953"/>
            <geometry>
                <box size="1 0.2 0.2" />
            </geometry>
            <material name="Cyan">
                <color rgba="0 1.0 1.0 1.0"/>
            </material>
        </visual>
        <collision>
            <origin xyz="-0.2499999999999999 0.43301270189221935 0" rpy="0 0 2.0943951023931953"/>
            <geometry>
                <box size="1 0.2 0.2" />
            </geometry>
        </collision>
    </link>
    <link name="LowerLeg2">
        <inertial>
            <origin xyz="0 0 -0.5" rpy="0 0 2.0943951023931953"/>
            <mass value="1" />
            <inertia ixx="100" ixy="0" ixz="0" iyy="100" iyz="0" izz="100" />
        </inertial>
        <visual>
            <origin xyz="0 0 -0.5" rpy="0 0 2.0943951023931953"/>
            <geometry>
                <box size="0.2 0.2 1" />
            </geometry>
            <material name="Cyan">
                <color rgba="0 1.0 1.0 1.0"/>
            </material>
        </visual>
        <collision>
            <origin xyz="0 0 -0.5" rpy="0 0 2.0943951023931953"/>
            <geometry>
                <box size="0.2 0.2 1" />
            </geometry>
        </collision>
    </link>
    <joint name="Torso_UppperLeg2" type="revolute">
       <parent link="Torso"/>
       <child  link="UppperLeg2"/>
       <origin rpy="0 0 0" xyz="-0.2499999999999999 0.43301270189221935 1"/>
     <axis xyz="0.8660254037844387 0.4999999999999998 0"/>
       <limit effort="0.0" lower="-3.14159" upper="3.14159" velocity="0.0"/>
    </joint>
    <joint name="UppperLeg2_LowerLeg2" type="revolute">
       <parent link="UppperLeg2"/>
       <child  link="LowerLeg2"/>
       <origin rpy="0 0 0" xyz="-0.4999999999999998 0.8660254037844387 0"/>
     <axis xyz="0.8660254037844387 0.4999999999999998 0"/>
       <limit effort="0.0" lower="-3.14159" upper="3.14159" velocity="0.0"/>
    </joint>
    <link name="UppperLeg3">
        <inertial>
            <origin xyz="-0.5 6.123233995736766e-17 0" rpy="0 0 3.141592653589793"/>
            <mass value="1" />
            <inertia ixx="100" ixy="0" ixz="0" iyy="100" iyz="0" izz="100" />
        </inertial>
        <visual>
            <origin xyz="-0.5 6.123233995736766e-17 0" rpy="0 0 3.141592653589793"/>
            <geometry>
                <box size="1 0.2 0.2" />
            </geometry>
            <material name="Cyan">
                <color rgba="0 1.0 1.0 1.0"/>
            </material>
        </visual>
        <collision>
            <origin xyz="-0.5 6.123233995736766e-17 0" rpy="0 0 3.141592653589793"/>
            <geometry>
                <box size="1 0.2 0.2" />
            </geometry>
        </collision>
    </link>
    <link name="LowerLeg3">
        <inertial>
            <origin xyz="0 0 -0.5" rpy="0 0 3.141592653589793"/>
            <mass value="1" />
            <inertia ixx="100" ixy="0" ixz="0" iyy="100" iyz="0" izz="100" />
        </inertial>
        <visual>
            <origin xyz="0 0 -0.5" rpy="0 0 3.141592653589793"/>
            <geometry>
                <box size="0.2 0.2 1" />
            </geometry>
            <material name="Cyan">
                <color rgba="0 1.0 1.0 1.0"/>
            </material>
        </visual>
        <collision>
            <origin xyz="0 0 -0.5" rpy="0 0 3.141592653589793"/>
            <geometry>
                <box size="0.2 0.2 1" />
            </geometry>
        </collision>
    </link>
    <joint name="Torso_UppperLeg3" type="revolute">
       <parent link="Torso"/>
       <child  link="UppperLeg3"/>
       <origin rpy="0 0 0" xyz="-0.5 6.123233995736766e-17 1"/>
     <axis xyz="1.2246467991473532e-16 1.0 0"/>
       <limit effort="0.0" lower="-3.14159" upper="3.14159" velocity="0.0"/>
    </joint>
    <joint name="UppperLeg3_LowerLeg3" type="revolute">
       <parent link="UppperLeg3"/>
       <child  link="LowerLeg3"/>
       <origin rpy="0 0 0" xyz="-1.0 1.2246467991473532e-16 0"/>
     <axis xyz="1.2246467991473532e-16 1.0 0"/>
       <limit effort="0.0" lower="-3.14159" upper="3.14159" velocity="0.0"/>
    </joint>
    <link name="UppperLeg4">
        <inertial>
            <origin xyz="-0.2500000000000002 -0.43301270189221924 0" rpy="0 0 4.1887902047863905"/>
            <mass value="1" />
            <inertia ixx="100" ixy="0" ixz="0" iyy="100" iyz="0" izz="100" />
        </inertial>
        <visual>
            <origin xyz="-0.2500000000000002 -0.43301270189221924 0" rpy="0 0 4.1887902047863905"/>
            <geometry>
                <box size="1 0.2 0.2" />
            </geometry>
            <material name="Cyan">
                <color rgba="0 1.0 1.0 1.0"/>
            </material>
        </visual>
        <collision>
            <origin xyz="-0.2500000000000002 -0.43301270189221924 0" rpy="0 0 4.1887902047863905"/>
            <geometry>
                <box size="1 0.2 0.2" />
            </geometry>
        </collision>
    </link>
    <link name="LowerLeg4">
        <inertial>
            <origin xyz="0 0 -0.5" rpy="0 0 4.1887902047863905"/>
            <mass value="1" />
            <inertia ixx="100" ixy="0" ixz="0" iyy="100" iyz="0" izz="100" />
        </inertial>
        <visual>
            <origin xyz="0 0 -0.5" rpy="0 0 4.1887902047863905"/>
            <geometry>
                <box size="0.2 0.2 1" />
            </geometry>
            <material name="Cyan">
                <color rgba="0 1.0 1.0 1.0"/>
            </material>
        </visual>
        <collision>
            <origin xyz="0 0 -0.5" rpy="0 0 4.1887902047863905"/>
            <geometry>
                <box size="0.2 0.2 1" />
            </geometry>
        </collision>
    </link>
    <joint name="Torso_UppperLeg4" type="revolute">
       <parent link="Torso"/>
       <child  link="UppperLeg4"/>
       <origin rpy="0 0 0" xyz="-0.2500000000000002 -0.43301270189221924 1"/>
     <axis xyz="0.8660254037844385 0.5000000000000004 0"/>
       <limit effort="0.0" lower="-3.14159" upper="3.14159" velocity="0.0"/>
    </joint>
    <joint name="UppperLeg4_LowerLeg4" type="revolute">
       <parent link="UppperLeg4"/>
       <child  link="LowerLeg4"/>
       <origin rpy="0 0 0" xyz="-0.5000000000000004 -0.8660254037844385 0"/>
     <axis xyz="0.8660254037844385 0.5000000000000004 0"/>
       <limit effort="0.0" lower="-3.14159" upper="3.14159" velocity="0.0"/>
    </joint>
    <link name="UppperLeg5">
        <inertial>
            <origin xyz="0.25000000000000006 -0.4330127018922193 0" rpy="0 0 5.235987755982989"/>
            <mass value="1" />
            <inertia ixx="100" ixy="0" ixz="0" iyy="100" iyz="0" izz="100" />
        </inertial>
        <visual>
            <origin xyz="0.25000000000000006 -0.4330127018922193 0" rpy="0 0 5.235987755982989"/>
            <geometry>
                <box size="1 0.2 0.2" />
            </geometry>
            <material name="Cyan">
                <color rgba="0 1.0 1.0 1.0"/>
            </material>
        </visual>
        <collision>
            <origin xyz="0.25000000000000006 -0.4330127018922193 0" rpy="0 0 5.235987755982989"/>
            <geometry>
                <box size="1 0.2 0.2" />
            </geometry>
        </collision>
    </link>
    <link name="LowerLeg5">
        <inertial>
            <origin xyz="0 0 -0.5" rpy="0 0 5.235987755982989"/>
            <mass value="1" />
            <inertia ixx="100" ixy="0" ixz="0" iyy="100" iyz="0" izz="100" />
        </inertial>
        <visual>
            <origin xyz="0 0 -0.5" rpy="0 0 5.235987755982989"/>
            <geometry>
                <box size="0.2 0.2 1" />
            </geometry>
            <material name="Cyan">
                <color rgba="0 1.0 1.0 1.0"/>
            </material>
        </visual>
        <collision>
            <origin xyz="0 0 -0.5" rpy="0 0 5.235987755982989"/>
            <geometry>
                <box size="0.2 0.2 1" />
            </geometry>
        </collision>
    </link>
    <joint name="Torso_UppperLeg5" type="revolute">
       <parent link="Torso"/>
       <child  link="UppperLeg5"/>
       <origin rpy="0 0 0" xyz="0.25000000000000006 -0.4330127018922193 1"/>
     <axis xyz="0.8660254037844386 0.5000000000000001 0"/>
       <limit effort="0.0" lower="-3.14159" upper="3.14159" velocity="0.0"/>
    </joint>
    <joint name="UppperLeg5_LowerLeg5" type="revolute">
       <parent link="UppperLeg5"/>
       <child  link="LowerLeg5"/>
       <origin rpy="0 0 0" xyz="0.5000000000000001 -0.8660254037844386 0"/>
     <axis xyz="0.8660254037844386 0.5000000000000001 0"/>
       <limit effort="0.0" lower="-3.14159" upper="3.14159" velocity="0.0"/>
    </joint>
</robot>