<robot name = "robot">
    <link name="Torso">
        <inertial>
            <origin xyz="0 0 1" rpy="0 0 0"/>
            <mass value="1" />
            <inertia ixx="100" ixy="0" ixz="0" iyy="100" iyz="0" izz="100" />
        </inertial>
        <visual>
            <origin xyz="0 0 1" rpy="0 0 0"/>
            <geometry>
                <sphere radius="0.5" />
            </geometry>
            <material name="Cyan">
                <color rgba="0 1.0 1.0 1.0"/>
            </material>
        </visual>
        <collision>
            <origin xyz="0 0 1" rpy="0 0 0"/>
            <geometry>
                <sphere radius="0.5" />
            </geometry>
        </collision>
    </link>
    <link name="UppperLeg0">
        <inertial>
            <origin xyz="0.5 0.0 0" rpy="0 0 0.0"/>
            <mass value="1" />
            <inertia ixx="100" ixy="0" ixz="0" iyy="100" iyz="0" izz="100" />
        </inertial>
        <visual>
            <origin xyz="0.5 0.0 0" rpy="0 0 0.0"/>
            <geometry>
                <box size="1 0.2 0.2" />
            </geometry>
            <material name="Cyan">
                <color rgba="0 1.0 1.0 1.0"/>
            </material>
        </visual>
        <collision>
            <origin xyz="0.5 0.0 0" rpy="0 0 0.0"/>
            <geometry>
                <box size="1 0.2 0.2" />
            </geometry>
        </collision>
    </link>
    <link name="LowerLeg0">
        <inertial>
            <origin xyz="0 0 -0.5" rpy="0 0 0.0"/>
            <mass value="1" />
            <inertia ixx="100" ixy="0" ixz="0" iyy="100" iyz="0" izz="100" />
        </inertial>
        <visual>
            <origin xyz="0 0 -0.5" rpy="0 0 0.0"/>
            <geometry>
                <box size="0.2 0.2 1" />
            </geometry>
            <material name="Cyan">
                <color rgba="0 1.0 1.0 1.0"/>
            </material>
        </visual>
        <collision>
            <origin xyz="0 0 -0.5" rpy="0 0 0.0"/>
            <geometry>
                <box size="0.2 0.2 1" />
            </geometry>
        </collision>
    </link>
    <joint name="Torso_UppperLeg0" type="revolute">
       <parent link="Torso"/>
       <child  link="UppperLeg0"/>
       <origin rpy="0 0 0" xyz="0.5 0.0 1"/>
     <axis xyz="0.0 1.0 0"/>
       <limit effort="0.0" lower="-3.14159" upper="3.14159" velocity="0.0"/>
    </joint>
    <joint name="UppperLeg0_LowerLeg0" type="revolute">
       <parent link="UppperLeg0"/>
       <child  link="LowerLeg0"/>
       <origin rpy="0 0 0" xyz="1.0 0.0 0"/>
     <axis xyz="0.0 1.0 0"/>
       <limit effort="0.0" lower="-3.14159" upper="3.14159" velocity="0.0"/>
    </joint>
    <link name="UppperLeg1">
        <inertial>
            <origin xyz="0.45677272882130043 0.2033683215379001 0" rpy="0 0 0.4188790204786391"/>
            <mass value="1" />
            <inertia ixx="100" ixy="0" ixz="0" iyy="100" iyz="0" izz="100" />
        </inertial>
        <visual>
            <origin xyz="0.45677272882130043 0.2033683215379001 0" rpy="0 0 0.4188790204786391"/>
            <geometry>
                <box size="1 0.2 0.2" />
            </geometry>
            <material name="Cyan">
                <color rgba="0 1.0 1.0 1.0"/>
            </material>
        </visual>
        <collision>
            <origin xyz="0.45677272882130043 0.2033683215379001 0" rpy="0 0 0.4188790204786391"/>
            <geometry>
                <box size="1 0.2 0.2" />
            </geometry>
        </collision>
    </link>
    <link name="LowerLeg1">
        <inertial>
            <origin xyz="0 0 -0.5" rpy="0 0 0.4188790204786391"/>
            <mass value="1" />
            <inertia ixx="100" ixy="0" ixz="0" iyy="100" iyz="0" izz="100" />
        </inertial>
        <visual>
            <origin xyz="0 0 -0.5" rpy="0 0 0.4188790204786391"/>
            <geometry>
                <box size="0.2 0.2 1" />
            </geometry>
            <material name="Cyan">
                <color rgba="0 1.0 1.0 1.0"/>
            </material>
        </visual>
        <collision>
            <origin xyz="0 0 -0.5" rpy="0 0 0.4188790204786391"/>
            <geometry>
                <box size="0.2 0.2 1" />
            </geometry>
        </collision>
    </link>
    <joint name="Torso_UppperLeg1" type="revolute">
       <parent link="Torso"/>
       <child  link="UppperLeg1"/>
       <origin rpy="0 0 0" xyz="0.45677272882130043 0.2033683215379001 1"/>
     <axis xyz="0.4067366430758002 0.9135454576426009 0"/>
       <limit effort="0.0" lower="-3.14159" upper="3.14159" velocity="0.0"/>
    </joint>
    <joint name="UppperLeg1_LowerLeg1" type="revolute">
       <parent link="UppperLeg1"/>
       <child  link="LowerLeg1"/>
       <origin rpy="0 0 0" xyz="0.9135454576426009 0.4067366430758002 0"/>
     <axis xyz="0.4067366430758002 0.9135454576426009 0"/>
       <limit effort="0.0" lower="-3.14159" upper="3.14159" velocity="0.0"/>
    </joint>
    <link name="UppperLeg2">
        <inertial>
            <origin xyz="0.3345653031794291 0.3715724127386971 0" rpy="0 0 0.8377580409572782"/>
            <mass value="1" />
            <inertia ixx="100" ixy="0" ixz="0" iyy="100" iyz="0" izz="100" />
        </inertial>
        <visual>
            <origin xyz="0.3345653031794291 0.3715724127386971 0" rpy="0 0 0.8377580409572782"/>
            <geometry>
                <box size="1 0.2 0.2" />
            </geometry>
            <material name="Cyan">
                <color rgba="0 1.0 1.0 1.0"/>
            </material>
        </visual>
        <collision>
            <origin xyz="0.3345653031794291 0.3715724127386971 0" rpy="0 0 0.8377580409572782"/>
            <geometry>
                <box size="1 0.2 0.2" />
            </geometry>
        </collision>
    </link>
    <link name="LowerLeg2">
        <inertial>
            <origin xyz="0 0 -0.5" rpy="0 0 0.8377580409572782"/>
            <mass value="1" />
            <inertia ixx="100" ixy="0" ixz="0" iyy="100" iyz="0" izz="100" />
        </inertial>
        <visual>
            <origin xyz="0 0 -0.5" rpy="0 0 0.8377580409572782"/>
            <geometry>
                <box size="0.2 0.2 1" />
            </geometry>
            <material name="Cyan">
                <color rgba="0 1.0 1.0 1.0"/>
            </material>
        </visual>
        <collision>
            <origin xyz="0 0 -0.5" rpy="0 0 0.8377580409572782"/>
            <geometry>
                <box size="0.2 0.2 1" />
            </geometry>
        </collision>
    </link>
    <joint name="Torso_UppperLeg2" type="revolute">
       <parent link="Torso"/>
       <child  link="UppperLeg2"/>
       <origin rpy="0 0 0" xyz="0.3345653031794291 0.3715724127386971 1"/>
     <axis xyz="0.7431448254773942 0.6691306063588582 0"/>
       <limit effort="0.0" lower="-3.14159" upper="3.14159" velocity="0.0"/>
    </joint>
    <joint name="UppperLeg2_LowerLeg2" type="revolute">
       <parent link="UppperLeg2"/>
       <child  link="LowerLeg2"/>
       <origin rpy="0 0 0" xyz="0.6691306063588582 0.7431448254773942 0"/>
     <axis xyz="0.7431448254773942 0.6691306063588582 0"/>
       <limit effort="0.0" lower="-3.14159" upper="3.14159" velocity="0.0"/>
    </joint>
    <link name="UppperLeg3">
        <inertial>
            <origin xyz="0.15450849718747373 0.47552825814757677 0" rpy="0 0 1.2566370614359172"/>
            <mass value="1" />
            <inertia ixx="100" ixy="0" ixz="0" iyy="100" iyz="0" izz="100" />
        </inertial>
        <visual>
            <origin xyz="0.15450849718747373 0.47552825814757677 0" rpy="0 0 1.2566370614359172"/>
            <geometry>
                <box size="1 0.2 0.2" />
            </geometry>
            <material name="Cyan">
                <color rgba="0 1.0 1.0 1.0"/>
            </material>
        </visual>
        <collision>
            <origin xyz="0.15450849718747373 0.47552825814757677 0" rpy="0 0 1.2566370614359172"/>
            <geometry>
                <box size="1 0.2 0.2" />
            </geometry>
        </collision>
    </link>
    <link name="LowerLeg3">
        <inertial>
            <origin xyz="0 0 -0.5" rpy="0 0 1.2566370614359172"/>
            <mass value="1" />
            <inertia ixx="100" ixy="0" ixz="0" iyy="100" iyz="0" izz="100" />
        </inertial>
        <visual>
            <origin xyz="0 0 -0.5" rpy="0 0 1.2566370614359172"/>
            <geometry>
                <box size="0.2 0.2 1" />
            </geometry>
            <material name="Cyan">
                <color rgba="0 1.0 1.0 1.0"/>
            </material>
        </visual>
        <collision>
            <origin xyz="0 0 -0.5" rpy="0 0 1.2566370614359172"/>
            <geometry>
                <box size="0.2 0.2 1" />
            </geometry>
        </collision>
    </link>
    <joint name="Torso_UppperLeg3" type="revolute">
       <parent link="Torso"/>
       <child  link="UppperLeg3"/>
       <origin rpy="0 0 0" xyz="0.15450849718747373 0.47552825814757677 1"/>
     <axis xyz="0.9510565162951535 0.30901699437494745 0"/>
       <limit effort="0.0" lower="-3.14159" upper="3.14159" velocity="0.0"/>
    </joint>
    <joint name="UppperLeg3_LowerLeg3" type="revolute">
       <parent link="UppperLeg3"/>
       <child  link="LowerLeg3"/>
       <origin rpy="0 0 0" xyz="0.30901699437494745 0.9510565162951535 0"/>
     <axis xyz="0.9510565162951535 0.30901699437494745 0"/>
       <limit effort="0.0" lower="-3.14159" upper="3.14159" velocity="0.0"/>
    </joint>
    <link name="UppperLeg4">
        <inertial>
            <origin xyz="-0.05226423163382678 0.49726094768413664 0" rpy="0 0 1.6755160819145565"/>
            <mass value="1" />
            <inertia ixx="100" ixy="0" ixz="0" iyy="100" iyz="0" izz="100" />
        </inertial>
        <visual>
            <origin xyz="-0.05226423163382678 0.49726094768413664 0" rpy="0 0 1.6755160819145565"/>
            <geometry>
                <box size="1 0.2 0.2" />
            </geometry>
            <material name="Cyan">
                <color rgba="0 1.0 1.0 1.0"/>
            </material>
        </visual>
        <collision>
            <origin xyz="-0.05226423163382678 0.49726094768413664 0" rpy="0 0 1.6755160819145565"/>
            <geometry>
                <box size="1 0.2 0.2" />
            </geometry>
        </collision>
    </link>
    <link name="LowerLeg4">
        <inertial>
            <origin xyz="0 0 -0.5" rpy="0 0 1.6755160819145565"/>
            <mass value="1" />
            <inertia ixx="100" ixy="0" ixz="0" iyy="100" iyz="0" izz="100" />
        </inertial>
        <visual>
            <origin xyz="0 0 -0.5" rpy="0 0 1.6755160819145565"/>
            <geometry>
                <box size="0.2 0.2 1" />
            </geometry>
            <material name="Cyan">
                <color rgba="0 1.0 1.0 1.0"/>
            </material>
        </visual>
        <collision>
            <origin xyz="0 0 -0.5" rpy="0 0 1.6755160819145565"/>
            <geometry>
                <box size="0.2 0.2 1" />
            </geometry>
        </collision>
    </link>
    <joint name="Torso_UppperLeg4" type="revolute">
       <parent link="Torso"/>
       <child  link="UppperLeg4"/>
       <origin rpy="0 0 0" xyz="-0.05226423163382678 0.49726094768413664 1"/>
     <axis xyz="0.9945218953682733 0.10452846326765355 0"/>
       <limit effort="0.0" lower="-3.14159" upper="3.14159" velocity="0.0"/>
    </joint>
    <joint name="UppperLeg4_LowerLeg4" type="revolute">
       <parent link="UppperLeg4"/>
       <child  link="LowerLeg4"/>
       <origin rpy="0 0 0" xyz="-0.10452846326765355 0.9945218953682733 0"/>
     <axis xyz="0.9945218953682733 0.10452846326765355 0"/>
       <limit effort="0.0" lower="-3.14159" upper="3.14159" velocity="0.0"/>
    </joint>
    <link name="UppperLeg5">
        <inertial>
            <origin xyz="-0.2499999999999999 0.43301270189221935 0" rpy="0 0 2.0943951023931953"/>
            <mass value="1" />
            <inertia ixx="100" ixy="0" ixz="0" iyy="100" iyz="0" izz="100" />
        </inertial>
        <visual>
            <origin xyz="-0.2499999999999999 0.43301270189221935 0" rpy="0 0 2.0943951023931953"/>
            <geometry>
                <box size="1 0.2 0.2" />
            </geometry>
            <material name="Cyan">
                <color rgba="0 1.0 1.0 1.0"/>
            </material>
        </visual>
        <collision>
            <origin xyz="-0.2499999999999999 0.43301270189221935 0" rpy="0 0 2.0943951023931953"/>
            <geometry>
                <box size="1 0.2 0.2" />
            </geometry>
        </collision>
    </link>
    <link name="LowerLeg5">
        <inertial>
            <origin xyz="0 0 -0.5" rpy="0 0 2.0943951023931953"/>
            <mass value="1" />
            <inertia ixx="100" ixy="0" ixz="0" iyy="100" iyz="0" izz="100" />
        </inertial>
        <visual>
            <origin xyz="0 0 -0.5" rpy="0 0 2.0943951023931953"/>
            <geometry>
                <box size="0.2 0.2 1" />
            </geometry>
            <material name="Cyan">
                <color rgba="0 1.0 1.0 1.0"/>
            </material>
        </visual>
        <collision>
            <origin xyz="0 0 -0.5" rpy="0 0 2.0943951023931953"/>
            <geometry>
                <box size="0.2 0.2 1" />
            </geometry>
        </collision>
    </link>
    <joint name="Torso_UppperLeg5" type="revolute">
       <parent link="Torso"/>
       <child  link="UppperLeg5"/>
       <origin rpy="0 0 0" xyz="-0.2499999999999999 0.43301270189221935 1"/>
     <axis xyz="0.8660254037844387 0.4999999999999998 0"/>
       <limit effort="0.0" lower="-3.14159" upper="3.14159" velocity="0.0"/>
    </joint>
    <joint name="UppperLeg5_LowerLeg5" type="revolute">
       <parent link="UppperLeg5"/>
       <child  link="LowerLeg5"/>
       <origin rpy="0 0 0" xyz="-0.4999999999999998 0.8660254037844387 0"/>
     <axis xyz="0.8660254037844387 0.4999999999999998 0"/>
       <limit effort="0.0" lower="-3.14159" upper="3.14159" velocity="0.0"/>
    </joint>
    <link name="UppperLeg6">
        <inertial>
            <origin xyz="-0.40450849718747367 0.2938926261462366 0" rpy="0 0 2.5132741228718345"/>
            <mass value="1" />
            <inertia ixx="100" ixy="0" ixz="0" iyy="100" iyz="0" izz="100" />
        </inertial>
        <visual>
            <origin xyz="-0.40450849718747367 0.2938926261462366 0" rpy="0 0 2.5132741228718345"/>
            <geometry>
                <box size="1 0.2 0.2" />
            </geometry>
            <material name="Cyan">
                <color rgba="0 1.0 1.0 1.0"/>
            </material>
        </visual>
        <collision>
            <origin xyz="-0.40450849718747367 0.2938926261462366 0" rpy="0 0 2.5132741228718345"/>
            <geometry>
                <box size="1 0.2 0.2" />
            </geometry>
        </collision>
    </link>
    <link name="LowerLeg6">
        <inertial>
            <origin xyz="0 0 -0.5" rpy="0 0 2.5132741228718345"/>
            <mass value="1" />
            <inertia ixx="100" ixy="0" ixz="0" iyy="100" iyz="0" izz="100" />
        </inertial>
        <visual>
            <origin xyz="0 0 -0.5" rpy="0 0 2.5132741228718345"/>
            <geometry>
                <box size="0.2 0.2 1" />
            </geometry>
            <material name="Cyan">
                <color rgba="0 1.0 1.0 1.0"/>
            </material>
        </visual>
        <collision>
            <origin xyz="0 0 -0.5" rpy="0 0 2.5132741228718345"/>
            <geometry>
                <box size="0.2 0.2 1" />
            </geometry>
        </collision>
    </link>
    <joint name="Torso_UppperLeg6" type="revolute">
       <parent link="Torso"/>
       <child  link="UppperLeg6"/>
       <origin rpy="0 0 0" xyz="-0.40450849718747367 0.2938926261462366 1"/>
     <axis xyz="0.5877852522924732 0.8090169943749473 0"/>
       <limit effort="0.0" lower="-3.14159" upper="3.14159" velocity="0.0"/>
    </joint>
    <joint name="UppperLeg6_LowerLeg6" type="revolute">
       <parent link="UppperLeg6"/>
       <child  link="LowerLeg6"/>
       <origin rpy="0 0 0" xyz="-0.8090169943749473 0.5877852522924732 0"/>
     <axis xyz="0.5877852522924732 0.8090169943749473 0"/>
       <limit effort="0.0" lower="-3.14159" upper="3.14159" velocity="0.0"/>
    </joint>
    <link name="UppperLeg7">
        <inertial>
            <origin xyz="-0.48907380036690284 0.10395584540887966 0" rpy="0 0 2.9321531433504737"/>
            <mass value="1" />
            <inertia ixx="100" ixy="0" ixz="0" iyy="100" iyz="0" izz="100" />
        </inertial>
        <visual>
            <origin xyz="-0.48907380036690284 0.10395584540887966 0" rpy="0 0 2.9321531433504737"/>
            <geometry>
                <box size="1 0.2 0.2" />
            </geometry>
            <material name="Cyan">
                <color rgba="0 1.0 1.0 1.0"/>
            </material>
        </visual>
        <collision>
            <origin xyz="-0.48907380036690284 0.10395584540887966 0" rpy="0 0 2.9321531433504737"/>
            <geometry>
                <box size="1 0.2 0.2" />
            </geometry>
        </collision>
    </link>
    <link name="LowerLeg7">
        <inertial>
            <origin xyz="0 0 -0.5" rpy="0 0 2.9321531433504737"/>
            <mass value="1" />
            <inertia ixx="100" ixy="0" ixz="0" iyy="100" iyz="0" izz="100" />
        </inertial>
        <visual>
            <origin xyz="0 0 -0.5" rpy="0 0 2.9321531433504737"/>
            <geometry>
                <box size="0.2 0.2 1" />
            </geometry>
            <material name="Cyan">
                <color rgba="0 1.0 1.0 1.0"/>
            </material>
        </visual>
        <collision>
            <origin xyz="0 0 -0.5" rpy="0 0 2.9321531433504737"/>
            <geometry>
                <box size="0.2 0.2 1" />
            </geometry>
        </collision>
    </link>
    <joint name="Torso_UppperLeg7" type="revolute">
       <parent link="Torso"/>
       <child  link="UppperLeg7"/>
       <origin rpy="0 0 0" xyz="-0.48907380036690284 0.10395584540887966 1"/>
     <axis xyz="0.20791169081775931 0.9781476007338057 0"/>
       <limit effort="0.0" lower="-3.14159" upper="3.14159" velocity="0.0"/>
    </joint>
    <joint name="UppperLeg7_LowerLeg7" type="revolute">
       <parent link="UppperLeg7"/>
       <child  link="LowerLeg7"/>
       <origin rpy="0 0 0" xyz="-0.9781476007338057 0.20791169081775931 0"/>
     <axis xyz="0.20791169081775931 0.9781476007338057 0"/>
       <limit effort="0.0" lower="-3.14159" upper="3.14159" velocity="0.0"/>
    </joint>
    <link name="UppperLeg8">
        <inertial>
            <origin xyz="-0.4890738003669028 -0.10395584540887975 0" rpy="0 0 3.351032163829113"/>
            <mass value="1" />
            <inertia ixx="100" ixy="0" ixz="0" iyy="100" iyz="0" izz="100" />
        </inertial>
        <visual>
            <origin xyz="-0.4890738003669028 -0.10395584540887975 0" rpy="0 0 3.351032163829113"/>
            <geometry>
                <box size="1 0.2 0.2" />
            </geometry>
            <material name="Cyan">
                <color rgba="0 1.0 1.0 1.0"/>
            </material>
        </visual>
        <collision>
            <origin xyz="-0.4890738003669028 -0.10395584540887975 0" rpy="0 0 3.351032163829113"/>
            <geometry>
                <box size="1 0.2 0.2" />
            </geometry>
        </collision>
    </link>
    <link name="LowerLeg8">
        <inertial>
            <origin xyz="0 0 -0.5" rpy="0 0 3.351032163829113"/>
            <mass value="1" />
            <inertia ixx="100" ixy="0" ixz="0" iyy="100" iyz="0" izz="100" />
        </inertial>
        <visual>
            <origin xyz="0 0 -0.5" rpy="0 0 3.351032163829113"/>
            <geometry>
                <box size="0.2 0.2 1" />
            </geometry>
            <material name="Cyan">
                <color rgba="0 1.0 1.0 1.0"/>
            </material>
        </visual>
        <collision>
            <origin xyz="0 0 -0.5" rpy="0 0 3.351032163829113"/>
            <geometry>
                <box size="0.2 0.2 1" />
            </geometry>
        </collision>
    </link>
    <joint name="Torso_UppperLeg8" type="revolute">
       <parent link="Torso"/>
       <child  link="UppperLeg8"/>
       <origin rpy="0 0 0" xyz="-0.4890738003669028 -0.10395584540887975 1"/>
     <axis xyz="0.2079116908177595 0.9781476007338056 0"/>
       <limit effort="0.0" lower="-3.14159" upper="3.14159" velocity="0.0"/>
    </joint>
    <joint name="UppperLeg8_LowerLeg8" type="revolute">
       <parent link="UppperLeg8"/>
       <child  link="LowerLeg8"/>
       <origin rpy="0 0 0" xyz="-0.9781476007338056 -0.2079116908177595 0"/>
     <axis xyz="0.2079116908177595 0.9781476007338056 0"/>
       <limit effort="0.0" lower="-3.14159" upper="3.14159" velocity="0.0"/>
    </joint>
    <link name="UppperLeg9">
        <inertial>
            <origin xyz="-0.4045084971874737 -0.2938926261462365 0" rpy="0 0 3.7699111843077517"/>
            <mass value="1" />
            <inertia ixx="100" ixy="0" ixz="0" iyy="100" iyz="0" izz="100" />
        </inertial>
        <visual>
            <origin xyz="-0.4045084971874737 -0.2938926261462365 0" rpy="0 0 3.7699111843077517"/>
            <geometry>
                <box size="1 0.2 0.2" />
            </geometry>
            <material name="Cyan">
                <color rgba="0 1.0 1.0 1.0"/>
            </material>
        </visual>
        <collision>
            <origin xyz="-0.4045084971874737 -0.2938926261462365 0" rpy="0 0 3.7699111843077517"/>
            <geometry>
                <box size="1 0.2 0.2" />
            </geometry>
        </collision>
    </link>
    <link name="LowerLeg9">
        <inertial>
            <origin xyz="0 0 -0.5" rpy="0 0 3.7699111843077517"/>
            <mass value="1" />
            <inertia ixx="100" ixy="0" ixz="0" iyy="100" iyz="0" izz="100" />
        </inertial>
        <visual>
            <origin xyz="0 0 -0.5" rpy="0 0 3.7699111843077517"/>
            <geometry>
                <box size="0.2 0.2 1" />
            </geometry>
            <material name="Cyan">
                <color rgba="0 1.0 1.0 1.0"/>
            </material>
        </visual>
        <collision>
            <origin xyz="0 0 -0.5" rpy="0 0 3.7699111843077517"/>
            <geometry>
                <box size="0.2 0.2 1" />
            </geometry>
        </collision>
    </link>
    <joint name="Torso_UppperLeg9" type="revolute">
       <parent link="Torso"/>
       <child  link="UppperLeg9"/>
       <origin rpy="0 0 0" xyz="-0.4045084971874737 -0.2938926261462365 1"/>
     <axis xyz="0.587785252292473 0.8090169943749475 0"/>
       <limit effort="0.0" lower="-3.14159" upper="3.14159" velocity="0.0"/>
    </joint>
    <joint name="UppperLeg9_LowerLeg9" type="revolute">
       <parent link="UppperLeg9"/>
       <child  link="LowerLeg9"/>
       <origin rpy="0 0 0" xyz="-0.8090169943749475 -0.587785252292473 0"/>
     <axis xyz="0.587785252292473 0.8090169943749475 0"/>
       <limit effort="0.0" lower="-3.14159" upper="3.14159" velocity="0.0"/>
    </joint>
    <link name="UppperLeg10">
        <inertial>
            <origin xyz="-0.2500000000000002 -0.43301270189221924 0" rpy="0 0 4.1887902047863905"/>
            <mass value="1" />
            <inertia ixx="100" ixy="0" ixz="0" iyy="100" iyz="0" izz="100" />
        </inertial>
        <visual>
            <origin xyz="-0.2500000000000002 -0.43301270189221924 0" rpy="0 0 4.1887902047863905"/>
            <geometry>
                <box size="1 0.2 0.2" />
            </geometry>
            <material name="Cyan">
                <color rgba="0 1.0 1.0 1.0"/>
            </material>
        </visual>
        <collision>
            <origin xyz="-0.2500000000000002 -0.43301270189221924 0" rpy="0 0 4.1887902047863905"/>
            <geometry>
                <box size="1 0.2 0.2" />
            </geometry>
        </collision>
    </link>
    <link name="LowerLeg10">
        <inertial>
            <origin xyz="0 0 -0.5" rpy="0 0 4.1887902047863905"/>
            <mass value="1" />
            <inertia ixx="100" ixy="0" ixz="0" iyy="100" iyz="0" izz="100" />
        </inertial>
        <visual>
            <origin xyz="0 0 -0.5" rpy="0 0 4.1887902047863905"/>
            <geometry>
                <box size="0.2 0.2 1" />
            </geometry>
            <material name="Cyan">
                <color rgba="0 1.0 1.0 1.0"/>
            </material>
        </visual>
        <collision>
            <origin xyz="0 0 -0.5" rpy="0 0 4.1887902047863905"/>
            <geometry>
                <box size="0.2 0.2 1" />
            </geometry>
        </collision>
    </link>
    <joint name="Torso_UppperLeg10" type="revolute">
       <parent link="Torso"/>
       <child  link="UppperLeg10"/>
       <origin rpy="0 0 0" xyz="-0.2500000000000002 -0.43301270189221924 1"/>
     <axis xyz="0.8660254037844385 0.5000000000000004 0"/>
       <limit effort="0.0" lower="-3.14159" upper="3.14159" velocity="0.0"/>
    </joint>
    <joint name="UppperLeg10_LowerLeg10" type="revolute">
       <parent link="UppperLeg10"/>
       <child  link="LowerLeg10"/>
       <origin rpy="0 0 0" xyz="-0.5000000000000004 -0.8660254037844385 0"/>
     <axis xyz="0.8660254037844385 0.5000000000000004 0"/>
       <limit effort="0.0" lower="-3.14159" upper="3.14159" velocity="0.0"/>
    </joint>
    <link name="UppperLeg11">
        <inertial>
            <origin xyz="-0.05226423163382668 -0.4972609476841367 0" rpy="0 0 4.60766922526503"/>
            <mass value="1" />
            <inertia ixx="100" ixy="0" ixz="0" iyy="100" iyz="0" izz="100" />
        </inertial>
        <visual>
            <origin xyz="-0.05226423163382668 -0.4972609476841367 0" rpy="0 0 4.60766922526503"/>
            <geometry>
                <box size="1 0.2 0.2" />
            </geometry>
            <material name="Cyan">
                <color rgba="0 1.0 1.0 1.0"/>
            </material>
        </visual>
        <collision>
            <origin xyz="-0.05226423163382668 -0.4972609476841367 0" rpy="0 0 4.60766922526503"/>
            <geometry>
                <box size="1 0.2 0.2" />
            </geometry>
        </collision>
    </link>
    <link name="LowerLeg11">
        <inertial>
            <origin xyz="0 0 -0.5" rpy="0 0 4.60766922526503"/>
            <mass value="1" />
            <inertia ixx="100" ixy="0" ixz="0" iyy="100" iyz="0" izz="100" />
        </inertial>
        <visual>
            <origin xyz="0 0 -0.5" rpy="0 0 4.60766922526503"/>
            <geometry>
                <box size="0.2 0.2 1" />
            </geometry>
            <material name="Cyan">
                <color rgba="0 1.0 1.0 1.0"/>
            </material>
        </visual>
        <collision>
            <origin xyz="0 0 -0.5" rpy="0 0 4.60766922526503"/>
            <geometry>
                <box size="0.2 0.2 1" />
            </geometry>
        </collision>
    </link>
    <joint name="Torso_UppperLeg11" type="revolute">
       <parent link="Torso"/>
       <child  link="UppperLeg11"/>
       <origin rpy="0 0 0" xyz="-0.05226423163382668 -0.4972609476841367 1"/>
     <axis xyz="0.9945218953682734 0.10452846326765336 0"/>
       <limit effort="0.0" lower="-3.14159" upper="3.14159" velocity="0.0"/>
    </joint>
    <joint name="UppperLeg11_LowerLeg11" type="revolute">
       <parent link="UppperLeg11"/>
       <child  link="LowerLeg11"/>
       <origin rpy="0 0 0" xyz="-0.10452846326765336 -0.9945218953682734 0"/>
     <axis xyz="0.9945218953682734 0.10452846326765336 0"/>
       <limit effort="0.0" lower="-3.14159" upper="3.14159" velocity="0.0"/>
    </joint>
    <link name="UppperLeg12">
        <inertial>
            <origin xyz="0.15450849718747361 -0.4755282581475768 0" rpy="0 0 5.026548245743669"/>
            <mass value="1" />
            <inertia ixx="100" ixy="0" ixz="0" iyy="100" iyz="0" izz="100" />
        </inertial>
        <visual>
            <origin xyz="0.15450849718747361 -0.4755282581475768 0" rpy="0 0 5.026548245743669"/>
            <geometry>
                <box size="1 0.2 0.2" />
            </geometry>
            <material name="Cyan">
                <color rgba="0 1.0 1.0 1.0"/>
            </material>
        </visual>
        <collision>
            <origin xyz="0.15450849718747361 -0.4755282581475768 0" rpy="0 0 5.026548245743669"/>
            <geometry>
                <box size="1 0.2 0.2" />
            </geometry>
        </collision>
    </link>
    <link name="LowerLeg12">
        <inertial>
            <origin xyz="0 0 -0.5" rpy="0 0 5.026548245743669"/>
            <mass value="1" />
            <inertia ixx="100" ixy="0" ixz="0" iyy="100" iyz="0" izz="100" />
        </inertial>
        <visual>
            <origin xyz="0 0 -0.5" rpy="0 0 5.026548245743669"/>
            <geometry>
                <box size="0.2 0.2 1" />
            </geometry>
            <material name="Cyan">
                <color rgba="0 1.0 1.0 1.0"/>
            </material>
        </visual>
        <collision>
            <origin xyz="0 0 -0.5" rpy="0 0 5.026548245743669"/>
            <geometry>
                <box size="0.2 0.2 1" />
            </geometry>
        </collision>
    </link>
    <joint name="Torso_UppperLeg12" type="revolute">
       <parent link="Torso"/>
       <child  link="UppperLeg12"/>
       <origin rpy="0 0 0" xyz="0.15450849718747361 -0.4755282581475768 1"/>
     <axis xyz="0.9510565162951536 0.30901699437494723 0"/>
       <limit effort="0.0" lower="-3.14159" upper="3.14159" velocity="0.0"/>
    </joint>
    <joint name="UppperLeg12_LowerLeg12" type="revolute">
       <parent link="UppperLeg12"/>
       <child  link="LowerLeg12"/>
       <origin rpy="0 0 0" xyz="0.30901699437494723 -0.9510565162951536 0"/>
     <axis xyz="0.9510565162951536 0.30901699437494723 0"/>
       <limit effort="0.0" lower="-3.14159" upper="3.14159" velocity="0.0"/>
    </joint>
    <link name="UppperLeg13">
        <inertial>
            <origin xyz="0.3345653031794289 -0.3715724127386973 0" rpy="0 0 5.445427266222308"/>
            <mass value="1" />
            <inertia ixx="100" ixy="0" ixz="0" iyy="100" iyz="0" izz="100" />
        </inertial>
        <visual>
            <origin xyz="0.3345653031794289 -0.3715724127386973 0" rpy="0 0 5.445427266222308"/>
            <geometry>
                <box size="1 0.2 0.2" />
            </geometry>
            <material name="Cyan">
                <color rgba="0 1.0 1.0 1.0"/>
            </material>
        </visual>
        <collision>
            <origin xyz="0.3345653031794289 -0.3715724127386973 0" rpy="0 0 5.445427266222308"/>
            <geometry>
                <box size="1 0.2 0.2" />
            </geometry>
        </collision>
    </link>
    <link name="LowerLeg13">
        <inertial>
            <origin xyz="0 0 -0.5" rpy="0 0 5.445427266222308"/>
            <mass value="1" />
            <inertia ixx="100" ixy="0" ixz="0" iyy="100" iyz="0" izz="100" />
        </inertial>
        <visual>
            <origin xyz="0 0 -0.5" rpy="0 0 5.445427266222308"/>
            <geometry>
                <box size="0.2 0.2 1" />
            </geometry>
            <material name="Cyan">
                <color rgba="0 1.0 1.0 1.0"/>
            </material>
        </visual>
        <collision>
            <origin xyz="0 0 -0.5" rpy="0 0 5.445427266222308"/>
            <geometry>
                <box size="0.2 0.2 1" />
            </geometry>
        </collision>
    </link>
    <joint name="Torso_UppperLeg13" type="revolute">
       <parent link="Torso"/>
       <child  link="UppperLeg13"/>
       <origin rpy="0 0 0" xyz="0.3345653031794289 -0.3715724127386973 1"/>
     <axis xyz="0.7431448254773946 0.6691306063588578 0"/>
       <limit effort="0.0" lower="-3.14159" upper="3.14159" velocity="0.0"/>
    </joint>
    <joint name="UppperLeg13_LowerLeg13" type="revolute">
       <parent link="UppperLeg13"/>
       <child  link="LowerLeg13"/>
       <origin rpy="0 0 0" xyz="0.6691306063588578 -0.7431448254773946 0"/>
     <axis xyz="0.7431448254773946 0.6691306063588578 0"/>
       <limit effort="0.0" lower="-3.14159" upper="3.14159" velocity="0.0"/>
    </joint>
    <link name="UppperLeg14">
        <inertial>
            <origin xyz="0.4567727288213005 -0.20336832153790008 0" rpy="0 0 5.8643062867009474"/>
            <mass value="1" />
            <inertia ixx="100" ixy="0" ixz="0" iyy="100" iyz="0" izz="100" />
        </inertial>
        <visual>
            <origin xyz="0.4567727288213005 -0.20336832153790008 0" rpy="0 0 5.8643062867009474"/>
            <geometry>
                <box size="1 0.2 0.2" />
            </geometry>
            <material name="Cyan">
                <color rgba="0 1.0 1.0 1.0"/>
            </material>
        </visual>
        <collision>
            <origin xyz="0.4567727288213005 -0.20336832153790008 0" rpy="0 0 5.8643062867009474"/>
            <geometry>
                <box size="1 0.2 0.2" />
            </geometry>
        </collision>
    </link>
    <link name="LowerLeg14">
        <inertial>
            <origin xyz="0 0 -0.5" rpy="0 0 5.8643062867009474"/>
            <mass value="1" />
            <inertia ixx="100" ixy="0" ixz="0" iyy="100" iyz="0" izz="100" />
        </inertial>
        <visual>
            <origin xyz="0 0 -0.5" rpy="0 0 5.8643062867009474"/>
            <geometry>
                <box size="0.2 0.2 1" />
            </geometry>
            <material name="Cyan">
                <color rgba="0 1.0 1.0 1.0"/>
            </material>
        </visual>
        <collision>
            <origin xyz="0 0 -0.5" rpy="0 0 5.8643062867009474"/>
            <geometry>
                <box size="0.2 0.2 1" />
            </geometry>
        </collision>
    </link>
    <joint name="Torso_UppperLeg14" type="revolute">
       <parent link="Torso"/>
       <child  link="UppperLeg14"/>
       <origin rpy="0 0 0" xyz="0.4567727288213005 -0.20336832153790008 1"/>
     <axis xyz="0.40673664307580015 0.913545457642601 0"/>
       <limit effort="0.0" lower="-3.14159" upper="3.14159" velocity="0.0"/>
    </joint>
    <joint name="UppperLeg14_LowerLeg14" type="revolute">
       <parent link="UppperLeg14"/>
       <child  link="LowerLeg14"/>
       <origin rpy="0 0 0" xyz="0.913545457642601 -0.40673664307580015 0"/>
     <axis xyz="0.40673664307580015 0.913545457642601 0"/>
       <limit effort="0.0" lower="-3.14159" upper="3.14159" velocity="0.0"/>
    </joint>
</robot>