<robot name = "robot">
    <link name="Torso">
        <inertial>
            <origin xyz="0 0 1" rpy="0 0 0"/>
            <mass value="1" />
            <inertia ixx="100" ixy="0" ixz="0" iyy="100" iyz="0" izz="100" />
        </inertial>
        <visual>
            <origin xyz="0 0 1" rpy="0 0 0"/>
            <geometry>
                <sphere radius="0.5" />
            </geometry>
            <material name="Cyan">
                <color rgba="0 1.0 1.0 1.0"/>
            </material>
        </visual>
        <collision>
            <origin xyz="0 0 1" rpy="0 0 0"/>
            <geometry>
                <sphere radius="0.5" />
            </geometry>
        </collision>
    </link>
    <link name="UppperLeg0">
        <inertial>
            <origin xyz="0.5 0.0 0" rpy="0 0 0.0"/>
            <mass value="1" />
            <inertia ixx="100" ixy="0" ixz="0" iyy="100" iyz="0" izz="100" />
        </inertial>
        <visual>
            <origin xyz="0.5 0.0 0" rpy="0 0 0.0"/>
            <geometry>
                <box size="1 0.2 0.2" />
            </geometry>
            <material name="Cyan">
                <color rgba="0 1.0 1.0 1.0"/>
            </material>
        </visual>
        <collision>
            <origin xyz="0.5 0.0 0" rpy="0 0 0.0"/>
            <geometry>
                <box size="1 0.2 0.2" />
            </geometry>
        </collision>
    </link>
    <link name="LowerLeg0">
        <inertial>
            <origin xyz="0 0 -0.5" rpy="0 0 0.0"/>
            <mass value="1" />
            <inertia ixx="100" ixy="0" ixz="0" iyy="100" iyz="0" izz="100" />
        </inertial>
        <visual>
            <origin xyz="0 0 -0.5" rpy="0 0 0.0"/>
            <geometry>
                <box size="0.2 0.2 1" />
            </geometry>
            <material name="Cyan">
                <color rgba="0 1.0 1.0 1.0"/>
            </material>
        </visual>
        <collision>
            <origin xyz="0 0 -0.5" rpy="0 0 0.0"/>
            <geometry>
                <box size="0.2 0.2 1" />
            </geometry>
        </collision>
    </link>
    <joint name="Torso_UppperLeg0" type="revolute">
       <parent link="Torso"/>
       <child  link="UppperLeg0"/>
       <origin rpy="0 0 0" xyz="0.5 0.0 1"/>
     <axis xyz="0.0 1.0 0"/>
       <limit effort="0.0" lower="-3.14159" upper="3.14159" velocity="0.0"/>
    </joint>
    <joint name="UppperLeg0_LowerLeg0" type="revolute">
       <parent link="UppperLeg0"/>
       <child  link="LowerLeg0"/>
       <origin rpy="0 0 0" xyz="1.0 0.0 0"/>
     <axis xyz="0.0 1.0 0"/>
       <limit effort="0.0" lower="-3.14159" upper="3.14159" velocity="0.0"/>
    </joint>
    <link name="UppperLeg1">
        <inertial>
            <origin xyz="0.15450849718747373 0.47552825814757677 0" rpy="0 0 1.2566370614359172"/>
            <mass value="1" />
            <inertia ixx="100" ixy="0" ixz="0" iyy="100" iyz="0" izz="100" />
        </inertial>
        <visual>
            <origin xyz="0.15450849718747373 0.47552825814757677 0" rpy="0 0 1.2566370614359172"/>
            <geometry>
                <box size="1 0.2 0.2" />
            </geometry>
            <material name="Cyan">
                <color rgba="0 1.0 1.0 1.0"/>
            </material>
        </visual>
        <collision>
            <origin xyz="0.15450849718747373 0.47552825814757677 0" rpy="0 0 1.2566370614359172"/>
            <geometry>
                <box size="1 0.2 0.2" />
            </geometry>
        </collision>
    </link>
    <link name="LowerLeg1">
        <inertial>
            <origin xyz="0 0 -0.5" rpy="0 0 1.2566370614359172"/>
            <mass value="1" />
            <inertia ixx="100" ixy="0" ixz="0" iyy="100" iyz="0" izz="100" />
        </inertial>
        <visual>
            <origin xyz="0 0 -0.5" rpy="0 0 1.2566370614359172"/>
            <geometry>
                <box size="0.2 0.2 1" />
            </geometry>
            <material name="Cyan">
                <color rgba="0 1.0 1.0 1.0"/>
            </material>
        </visual>
        <collision>
            <origin xyz="0 0 -0.5" rpy="0 0 1.2566370614359172"/>
            <geometry>
                <box size="0.2 0.2 1" />
            </geometry>
        </collision>
    </link>
    <joint name="Torso_UppperLeg1" type="revolute">
       <parent link="Torso"/>
       <child  link="UppperLeg1"/>
       <origin rpy="0 0 0" xyz="0.15450849718747373 0.47552825814757677 1"/>
     <axis xyz="0.9510565162951535 0.30901699437494745 0"/>
       <limit effort="0.0" lower="-3.14159" upper="3.14159" velocity="0.0"/>
    </joint>
    <joint name="UppperLeg1_LowerLeg1" type="revolute">
       <parent link="UppperLeg1"/>
       <child  link="LowerLeg1"/>
       <origin rpy="0 0 0" xyz="0.30901699437494745 0.9510565162951535 0"/>
     <axis xyz="0.9510565162951535 0.30901699437494745 0"/>
       <limit effort="0.0" lower="-3.14159" upper="3.14159" velocity="0.0"/>
    </joint>
    <link name="UppperLeg2">
        <inertial>
            <origin xyz="-0.40450849718747367 0.2938926261462366 0" rpy="0 0 2.5132741228718345"/>
            <mass value="1" />
            <inertia ixx="100" ixy="0" ixz="0" iyy="100" iyz="0" izz="100" />
        </inertial>
        <visual>
            <origin xyz="-0.40450849718747367 0.2938926261462366 0" rpy="0 0 2.5132741228718345"/>
            <geometry>
                <box size="1 0.2 0.2" />
            </geometry>
            <material name="Cyan">
                <color rgba="0 1.0 1.0 1.0"/>
            </material>
        </visual>
        <collision>
            <origin xyz="-0.40450849718747367 0.2938926261462366 0" rpy="0 0 2.5132741228718345"/>
            <geometry>
                <box size="1 0.2 0.2" />
            </geometry>
        </collision>
    </link>
    <link name="LowerLeg2">
        <inertial>
            <origin xyz="0 0 -0.5" rpy="0 0 2.5132741228718345"/>
            <mass value="1" />
            <inertia ixx="100" ixy="0" ixz="0" iyy="100" iyz="0" izz="100" />
        </inertial>
        <visual>
            <origin xyz="0 0 -0.5" rpy="0 0 2.5132741228718345"/>
            <geometry>
                <box size="0.2 0.2 1" />
            </geometry>
            <material name="Cyan">
                <color rgba="0 1.0 1.0 1.0"/>
            </material>
        </visual>
        <collision>
            <origin xyz="0 0 -0.5" rpy="0 0 2.5132741228718345"/>
            <geometry>
                <box size="0.2 0.2 1" />
            </geometry>
        </collision>
    </link>
    <joint name="Torso_UppperLeg2" type="revolute">
       <parent link="Torso"/>
       <child  link="UppperLeg2"/>
       <origin rpy="0 0 0" xyz="-0.40450849718747367 0.2938926261462366 1"/>
     <axis xyz="0.5877852522924732 0.8090169943749473 0"/>
       <limit effort="0.0" lower="-3.14159" upper="3.14159" velocity="0.0"/>
    </joint>
    <joint name="UppperLeg2_LowerLeg2" type="revolute">
       <parent link="UppperLeg2"/>
       <child  link="LowerLeg2"/>
       <origin rpy="0 0 0" xyz="-0.8090169943749473 0.5877852522924732 0"/>
     <axis xyz="0.5877852522924732 0.8090169943749473 0"/>
       <limit effort="0.0" lower="-3.14159" upper="3.14159" velocity="0.0"/>
    </joint>
    <link name="UppperLeg3">
        <inertial>
            <origin xyz="-0.4045084971874737 -0.2938926261462365 0" rpy="0 0 3.7699111843077517"/>
            <mass value="1" />
            <inertia ixx="100" ixy="0" ixz="0" iyy="100" iyz="0" izz="100" />
        </inertial>
        <visual>
            <origin xyz="-0.4045084971874737 -0.2938926261462365 0" rpy="0 0 3.7699111843077517"/>
            <geometry>
                <box size="1 0.2 0.2" />
            </geometry>
            <material name="Cyan">
                <color rgba="0 1.0 1.0 1.0"/>
            </material>
        </visual>
        <collision>
            <origin xyz="-0.4045084971874737 -0.2938926261462365 0" rpy="0 0 3.7699111843077517"/>
            <geometry>
                <box size="1 0.2 0.2" />
            </geometry>
        </collision>
    </link>
    <link name="LowerLeg3">
        <inertial>
            <origin xyz="0 0 -0.5" rpy="0 0 3.7699111843077517"/>
            <mass value="1" />
            <inertia ixx="100" ixy="0" ixz="0" iyy="100" iyz="0" izz="100" />
        </inertial>
        <visual>
            <origin xyz="0 0 -0.5" rpy="0 0 3.7699111843077517"/>
            <geometry>
                <box size="0.2 0.2 1" />
            </geometry>
            <material name="Cyan">
                <color rgba="0 1.0 1.0 1.0"/>
            </material>
        </visual>
        <collision>
            <origin xyz="0 0 -0.5" rpy="0 0 3.7699111843077517"/>
            <geometry>
                <box size="0.2 0.2 1" />
            </geometry>
        </collision>
    </link>
    <joint name="Torso_UppperLeg3" type="revolute">
       <parent link="Torso"/>
       <child  link="UppperLeg3"/>
       <origin rpy="0 0 0" xyz="-0.4045084971874737 -0.2938926261462365 1"/>
     <axis xyz="0.587785252292473 0.8090169943749475 0"/>
       <limit effort="0.0" lower="-3.14159" upper="3.14159" velocity="0.0"/>
    </joint>
    <joint name="UppperLeg3_LowerLeg3" type="revolute">
       <parent link="UppperLeg3"/>
       <child  link="LowerLeg3"/>
       <origin rpy="0 0 0" xyz="-0.8090169943749475 -0.587785252292473 0"/>
     <axis xyz="0.587785252292473 0.8090169943749475 0"/>
       <limit effort="0.0" lower="-3.14159" upper="3.14159" velocity="0.0"/>
    </joint>
    <link name="UppperLeg4">
        <inertial>
            <origin xyz="0.15450849718747361 -0.4755282581475768 0" rpy="0 0 5.026548245743669"/>
            <mass value="1" />
            <inertia ixx="100" ixy="0" ixz="0" iyy="100" iyz="0" izz="100" />
        </inertial>
        <visual>
            <origin xyz="0.15450849718747361 -0.4755282581475768 0" rpy="0 0 5.026548245743669"/>
            <geometry>
                <box size="1 0.2 0.2" />
            </geometry>
            <material name="Cyan">
                <color rgba="0 1.0 1.0 1.0"/>
            </material>
        </visual>
        <collision>
            <origin xyz="0.15450849718747361 -0.4755282581475768 0" rpy="0 0 5.026548245743669"/>
            <geometry>
                <box size="1 0.2 0.2" />
            </geometry>
        </collision>
    </link>
    <link name="LowerLeg4">
        <inertial>
            <origin xyz="0 0 -0.5" rpy="0 0 5.026548245743669"/>
            <mass value="1" />
            <inertia ixx="100" ixy="0" ixz="0" iyy="100" iyz="0" izz="100" />
        </inertial>
        <visual>
            <origin xyz="0 0 -0.5" rpy="0 0 5.026548245743669"/>
            <geometry>
                <box size="0.2 0.2 1" />
            </geometry>
            <material name="Cyan">
                <color rgba="0 1.0 1.0 1.0"/>
            </material>
        </visual>
        <collision>
            <origin xyz="0 0 -0.5" rpy="0 0 5.026548245743669"/>
            <geometry>
                <box size="0.2 0.2 1" />
            </geometry>
        </collision>
    </link>
    <joint name="Torso_UppperLeg4" type="revolute">
       <parent link="Torso"/>
       <child  link="UppperLeg4"/>
       <origin rpy="0 0 0" xyz="0.15450849718747361 -0.4755282581475768 1"/>
     <axis xyz="0.9510565162951536 0.30901699437494723 0"/>
       <limit effort="0.0" lower="-3.14159" upper="3.14159" velocity="0.0"/>
    </joint>
    <joint name="UppperLeg4_LowerLeg4" type="revolute">
       <parent link="UppperLeg4"/>
       <child  link="LowerLeg4"/>
       <origin rpy="0 0 0" xyz="0.30901699437494723 -0.9510565162951536 0"/>
     <axis xyz="0.9510565162951536 0.30901699437494723 0"/>
       <limit effort="0.0" lower="-3.14159" upper="3.14159" velocity="0.0"/>
    </joint>
</robot>